Workbook

Sheet Guide
B1: PERSONAL BUDGET TRACKER | 2024
B2: All totals update automatically when you log data in Expense Log or Income Log
B4: HOW THIS TRACKER WORKS
B5: Step 1 | C5: Open EXPENSE LOG. Add one row per expense: Date, Description, Category, Amount.
B6: Step 2 | C6: Open INCOME LOG. Add one row per payment received: Date, Description, Source, Amount.
B7: Step 3 | C7: That is all. Every other sheet calculates automatically from your log entries.
B8: Step 4 | C8: Check MONTHLY SUMMARY for income vs expenses per month - fully automatic.
B9: Step 5 | C9: Check CATEGORY ANALYSIS to see where your money goes.
B10: Step 6 | C10: Check DASHBOARD for a quick year-to-date health check.
B12: SHEETS IN THIS WORKBOOK
B13: Guide | C13: This page.
B14: Dashboard | C14: Live KPI cards - total income, expenses, savings, savings rate for the year.
B15: Monthly Summary | C15: Income and expenses by month and category. SUMIFS formulas - add to logs and this updates.
B16: Expense Log | C16: MAIN DATA ENTRY for expenses. Add a new row for every expense.
B17: Income Log | C17: MAIN DATA ENTRY for income. Add a new row for every payment received.
B18: Category Analysis | C18: Annual totals and % breakdown by spending category. Auto-calculated.
B19: Savings Goals | C19: Set up to 10 goals. Update the Saved So Far column periodically.
B20: Annual Overview | C20: Month-by-month totals, running savings balance, key stats.
B22: RULES
B23: DO | C23: Enter data only in the WHITE cells in Expense Log and Income Log.
B24: DO | C24: Use the dropdown lists for Category and Source - exact spelling is critical for formulas.
B25: DO | C25: Enter dates in the format YYYY-MM-DD (example: 2024-01-15).
B26: DO | C26: Save regularly with Ctrl + S. Keep a backup copy.
B27: DO NOT | C27: Delete or rename any sheet tabs.
B28: DO NOT | C28: Delete header rows (rows 1 to 4 on any sheet).
B29: DO NOT | C29: Edit any coloured formula cells outside the log sheets.
B31: EXPENSE CATEGORIES - use exactly as shown below
B32: Housing | C32: Enter this exact text in the Category column of Expense Log.
B33: Food and Groceries | C33: Enter this exact text in the Category column of Expense Log.
B34: Transport | C34: Enter this exact text in the Category column of Expense Log.
B35: Health and Medical | C35: Enter this exact text in the Category column of Expense Log.
B36: Education | C36: Enter this exact text in the Category column of Expense Log.
B37: Shopping | C37: Enter this exact text in the Category column of Expense Log.
B38: Subscriptions | C38: Enter this exact text in the Category column of Expense Log.
B39: Entertainment | C39: Enter this exact text in the Category column of Expense Log.
B40: Travel | C40: Enter this exact text in the Category column of Expense Log.
B41: Savings and Investments | C41: Enter this exact text in the Category column of Expense Log.
B42: Miscellaneous | C42: Enter this exact text in the Category column of Expense Log.
B44: INCOME SOURCES - use exactly as shown below
B45: Salary | C45: Enter this exact text in the Source column of Income Log.
...

Sheet Dashboard
B1: BUDGET DASHBOARD | 2024
B2: All figures are year-to-date, calculated live from Expense Log and Income Log
B4: Total Income (YTD) | C4: Total Expenses (YTD) | D4: Net Savings (YTD) | E4: Savings Rate
B6: =SUMIFS('Income Log'!$E:$E,'Income Log'!$B:$B,">="&DATE(2024,1,1),'Income Log'!$B:$B,"<"&DATE(2025,1,1)) -> 281920 | C6: =SUMIFS('Expense Log'!$E:$E,'Expense Log'!$B:$B,">="&DATE(2024,1,1),'Expense Log'!$B:$B,"<"&DATE(2025,1,1)) -> 73548 | D6: =SUMIFS('Income Log'!$E:$E,'Income Log'!$B:$B,">="&DATE(2024,1,1),'Income Log'!$B:$B,"<"&DATE(2025,1,1))-SUMIFS('Expense Log'!$E:$E,'Expense Log'!$B:$B,">="&DATE(2024,1,1),'Expense Log'!$B:$B,"<"&DATE(2025,1,1)) -> 208372 | E6: =IF(SUMIFS('Income Log'!$E:$E,'Income Log'!$B:$B,">="&DATE(2024,1,1),'Income Log'!$B:$B,"<"&DATE(2025,1,1))=0,0,(SUMIFS('Income Log'!$E:$E,'Income Log'!$B:$B,">="&DATE(2024,1,1),'Income Log'!$B:$B,"<"&DATE(2025,1,1))-SUMIFS('Expense Log'!$E:$E,'Expense Log'!$B:$B,">="&DATE(2024,1,1),'Expense Log'!$B:$B,"<"&DATE(2025,1,1)))/SUMIFS('Income Log'!$E:$E,'Income Log'!$B:$B,">="&DATE(2024,1,1),'Income Log'!$B:$B,"<"&DATE(2025,1,1))) -> 0.73911748
B10: MONTHLY BREAKDOWN (auto-calculated)
B11: Month | C11: Income | D11: Expenses | E11: Net Savings
B12: January | C12: =SUMIFS('Income Log'!$E:$E,'Income Log'!$B:$B,">="&DATE(2024,1,1),'Income Log'!$B:$B,"<"&DATE(2024,2,1)) -> 88920 | D12: =SUMIFS('Expense Log'!$E:$E,'Expense Log'!$B:$B,">="&DATE(2024,1,1),'Expense Log'!$B:$B,"<"&DATE(2024,2,1)) -> 30548 | E12: =C12-D12 -> 58372
B13: February | C13: =SUMIFS('Income Log'!$E:$E,'Income Log'!$B:$B,">="&DATE(2024,2,1),'Income Log'!$B:$B,"<"&DATE(2024,3,1)) -> 93000 | D13: =SUMIFS('Expense Log'!$E:$E,'Expense Log'!$B:$B,">="&DATE(2024,2,1),'Expense Log'!$B:$B,"<"&DATE(2024,3,1)) -> 25000 | E13: =C13-D13 -> 68000
B14: March | C14: =SUMIFS('Income Log'!$E:$E,'Income Log'!$B:$B,">="&DATE(2024,3,1),'Income Log'!$B:$B,"<"&DATE(2024,4,1)) -> 100000 | D14: =SUMIFS('Expense Log'!$E:$E,'Expense Log'!$B:$B,">="&DATE(2024,3,1),'Expense Log'!$B:$B,"<"&DATE(2024,4,1)) -> 18000 | E14: =C14-D14 -> 82000
B15: April | C15: =SUMIFS('Income Log'!$E:$E,'Income Log'!$B:$B,">="&DATE(2024,4,1),'Income Log'!$B:$B,"<"&DATE(2024,5,1)) -> 0 | D15: =SUMIFS('Expense Log'!$E:$E,'Expense Log'!$B:$B,">="&DATE(2024,4,1),'Expense Log'!$B:$B,"<"&DATE(2024,5,1)) -> 0 | E15: =C15-D15 -> 0
B16: May | C16: =SUMIFS('Income Log'!$E:$E,'Income Log'!$B:$B,">="&DATE(2024,5,1),'Income Log'!$B:$B,"<"&DATE(2024,6,1)) -> 0 | D16: =SUMIFS('Expense Log'!$E:$E,'Expense Log'!$B:$B,">="&DATE(2024,5,1),'Expense Log'!$B:$B,"<"&DATE(2024,6,1)) -> 0 | E16: =C16-D16 -> 0
B17: June | C17: =SUMIFS('Income Log'!$E:$E,'Income Log'!$B:$B,">="&DATE(2024,6,1),'Income Log'!$B:$B,"<"&DATE(2024,7,1)) -> 0 | D17: =SUMIFS('Expense Log'!$E:$E,'Expense Log'!$B:$B,">="&DATE(2024,6,1),'Expense Log'!$B:$B,"<"&DATE(2024,7,1)) -> 0 | E17: =C17-D17 -> 0
B18: July | C18: =SUMIFS('Income Log'!$E:$E,'Income Log'!$B:$B,">="&DATE(2024,7,1),'Income Log'!$B:$B,"<"&DATE(2024,8,1)) -> 0 | D18: =SUMIFS('Expense Log'!$E:$E,'Expense Log'!$B:$B,">="&DATE(2024,7,1),'Expense Log'!$B:$B,"<"&DATE(2024,8,1)) -> 0 | E18: =C18-D18 -> 0
B19: August | C19: =SUMIFS('Income Log'!$E:$E,'Income Log'!$B:$B,">="&DATE(2024,8,1),'Income Log'!$B:$B,"<"&DATE(2024,9,1)) -> 0 | D19: =SUMIFS('Expense Log'!$E:$E,'Expense Log'!$B:$B,">="&DATE(2024,8,1),'Expense Log'!$B:$B,"<"&DATE(2024,9,1)) -> 0 | E19: =C19-D19 -> 0
B20: September | C20: =SUMIFS('Income Log'!$E:$E,'Income Log'!$B:$B,">="&DATE(2024,9,1),'Income Log'!$B:$B,"<"&DATE(2024,10,1)) -> 0 | D20: =SUMIFS('Expense Log'!$E:$E,'Expense Log'!$B:$B,">="&DATE(2024,9,1),'Expense Log'!$B:$B,"<"&DATE(2024,10,1)) -> 0 | E20: =C20-D20 -> 0
B21: October | C21: =SUMIFS('Income Log'!$E:$E,'Income Log'!$B:$B,">="&DATE(2024,10,1),'Income Log'!$B:$B,"<"&DATE(2024,11,1)) -> 0 | D21: =SUMIFS('Expense Log'!$E:$E,'Expense Log'!$B:$B,">="&DATE(2024,10,1),'Expense Log'!$B:$B,"<"&DATE(2024,11,1)) -> 0 | E21: =C21-D21 -> 0
B22: November | C22: =SUMIFS('Income Log'!$E:$E,'Income Log'!$B:$B,">="&DATE(2024,11,1),'Income Log'!$B:$B,"<"&DATE(2024,12,1)) -> 0 | D22: =SUMIFS('Expense Log'!$E:$E,'Expense Log'!$B:$B,">="&DATE(2024,11,1),'Expense Log'!$B:$B,"<"&DATE(2024,12,1)) -> 0 | E22: =C22-D22 -> 0
B23: December | C23: =SUMIFS('Income Log'!$E:$E,'Income Log'!$B:$B,">="&DATE(2024,12,1),'Income Log'!$B:$B,"<"&DATE(2025,1,1)) -> 0 | D23: =SUMIFS('Expense Log'!$E:$E,'Expense Log'!$B:$B,">="&DATE(2024,12,1),'Expense Log'!$B:$B,"<"&DATE(2025,1,1)) -> 0 | E23: =C23-D23 -> 0
B24: ANNUAL TOTAL | C24: =SUM(C12:C23) -> 281920 | D24: =SUM(D12:D23) -> 73548 | E24: =SUM(E12:E23) -> 208372

Sheet Monthly Summary
B1: MONTHLY SUMMARY | 2024 - Adds up automatically from Expense Log and Income Log
B2: Add rows to Expense Log or Income Log and this sheet updates instantly. Do not type in any coloured cell here.
B4: INCOME - add rows to Income Log to update
B5: Income Source | C5: Jan | D5: Feb | E5: Mar | F5: Apr | G5: May | H5: Jun | I5: Jul | J5: Aug | K5: Sep | L5: Oct | M5: Nov | N5: Dec | O5: Annual Total
B6: Salary | C6: =SUMIFS('Income Log'!$E:$E,'Income Log'!$D:$D,"Salary",'Income Log'!$B:$B,">="&DATE(2024,1,1),'Income Log'!$B:$B,"<"&DATE(2024,2,1)) -> 85000 | D6: =SUMIFS('Income Log'!$E:$E,'Income Log'!$D:$D,"Salary",'Income Log'!$B:$B,">="&DATE(2024,2,1),'Income Log'!$B:$B,"<"&DATE(2024,3,1)) -> 85000 | E6: =SUMIFS('Income Log'!$E:$E,'Income Log'!$D:$D,"Salary",'Income Log'!$B:$B,">="&DATE(2024,3,1),'Income Log'!$B:$B,"<"&DATE(2024,4,1)) -> 85000 | F6: =SUMIFS('Income Log'!$E:$E,'Income Log'!$D:$D,"Salary",'Income Log'!$B:$B,">="&DATE(2024,4,1),'Income Log'!$B:$B,"<"&DATE(2024,5,1)) -> 0 | G6: =SUMIFS('Income Log'!$E:$E,'Income Log'!$D:$D,"Salary",'Income Log'!$B:$B,">="&DATE(2024,5,1),'Income Log'!$B:$B,"<"&DATE(2024,6,1)) -> 0 | H6: =SUMIFS('Income Log'!$E:$E,'Income Log'!$D:$D,"Salary",'Income Log'!$B:$B,">="&DATE(2024,6,1),'Income Log'!$B:$B,"<"&DATE(2024,7,1)) -> 0 | I6: =SUMIFS('Income Log'!$E:$E,'Income Log'!$D:$D,"Salary",'Income Log'!$B:$B,">="&DATE(2024,7,1),'Income Log'!$B:$B,"<"&DATE(2024,8,1)) -> 0 | J6: =SUMIFS('Income Log'!$E:$E,'Income Log'!$D:$D,"Salary",'Income Log'!$B:$B,">="&DATE(2024,8,1),'Income Log'!$B:$B,"<"&DATE(2024,9,1)) -> 0 | K6: =SUMIFS('Income Log'!$E:$E,'Income Log'!$D:$D,"Salary",'Income Log'!$B:$B,">="&DATE(2024,9,1),'Income Log'!$B:$B,"<"&DATE(2024,10,1)) -> 0 | L6: =SUMIFS('Income Log'!$E:$E,'Income Log'!$D:$D,"Salary",'Income Log'!$B:$B,">="&DATE(2024,10,1),'Income Log'!$B:$B,"<"&DATE(2024,11,1)) -> 0 | M6: =SUMIFS('Income Log'!$E:$E,'Income Log'!$D:$D,"Salary",'Income Log'!$B:$B,">="&DATE(2024,11,1),'Income Log'!$B:$B,"<"&DATE(2024,12,1)) -> 0 | N6: =SUMIFS('Income Log'!$E:$E,'Income Log'!$D:$D,"Salary",'Income Log'!$B:$B,">="&DATE(2024,12,1),'Income Log'!$B:$B,"<"&DATE(2025,1,1)) -> 0 | O6: =SUM(C6:N6) -> 255000
B7: Freelance | C7: =SUMIFS('Income Log'!$E:$E,'Income Log'!$D:$D,"Freelance",'Income Log'!$B:$B,">="&DATE(2024,1,1),'Income Log'!$B:$B,"<"&DATE(2024,2,1)) -> 3500 | D7: =SUMIFS('Income Log'!$E:$E,'Income Log'!$D:$D,"Freelance",'Income Log'!$B:$B,">="&DATE(2024,2,1),'Income Log'!$B:$B,"<"&DATE(2024,3,1)) -> 8000 | E7: =SUMIFS('Income Log'!$E:$E,'Income Log'!$D:$D,"Freelance",'Income Log'!$B:$B,">="&DATE(2024,3,1),'Income Log'!$B:$B,"<"&DATE(2024,4,1)) -> 0 | F7: =SUMIFS('Income Log'!$E:$E,'Income Log'!$D:$D,"Freelance",'Income Log'!$B:$B,">="&DATE(2024,4,1),'Income Log'!$B:$B,"<"&DATE(2024,5,1)) -> 0 | G7: =SUMIFS('Income Log'!$E:$E,'Income Log'!$D:$D,"Freelance",'Income Log'!$B:$B,">="&DATE(2024,5,1),'Income Log'!$B:$B,"<"&DATE(2024,6,1)) -> 0 | H7: =SUMIFS('Income Log'!$E:$E,'Income Log'!$D:$D,"Freelance",'Income Log'!$B:$B,">="&DATE(2024,6,1),'Income Log'!$B:$B,"<"&DATE(2024,7,1)) -> 0 | I7: =SUMIFS('Income Log'!$E:$E,'Income Log'!$D:$D,"Freelance",'Income Log'!$B:$B,">="&DATE(2024,7,1),'Income Log'!$B:$B,"<"&DATE(2024,8,1)) -> 0 | J7: =SUMIFS('Income Log'!$E:$E,'Income Log'!$D:$D,"Freelance",'Income Log'!$B:$B,">="&DATE(2024,8,1),'Income Log'!$B:$B,"<"&DATE(2024,9,1)) -> 0 | K7: =SUMIFS('Income Log'!$E:$E,'Income Log'!$D:$D,"Freelance",'Income Log'!$B:$B,">="&DATE(2024,9,1),'Income Log'!$B:$B,"<"&DATE(2024,10,1)) -> 0 | L7: =SUMIFS('Income Log'!$E:$E,'Income Log'!$D:$D,"Freelance",'Income Log'!$B:$B,">="&DATE(2024,10,1),'Income Log'!$B:$B,"<"&DATE(2024,11,1)) -> 0 | M7: =SUMIFS('Income Log'!$E:$E,'Income Log'!$D:$D,"Freelance",'Income Log'!$B:$B,">="&DATE(2024,11,1),'Income Log'!$B:$B,"<"&DATE(2024,12,1)) -> 0 | N7: =SUMIFS('Income Log'!$E:$E,'Income Log'!$D:$D,"Freelance",'Income Log'!$B:$B,">="&DATE(2024,12,1),'Income Log'!$B:$B,"<"&DATE(2025,1,1)) -> 0 | O7: =SUM(C7:N7) -> 11500
B8: Rental Income | C8: =SUMIFS('Income Log'!$E:$E,'Income Log'!$D:$D,"Rental Income",'Income Log'!$B:$B,">="&DATE(2024,1,1),'Income Log'!$B:$B,"<"&DATE(2024,2,1)) -> 0 | D8: =SUMIFS('Income Log'!$E:$E,'Income Log'!$D:$D,"Rental Income",'Income Log'!$B:$B,">="&DATE(2024,2,1),'Income Log'!$B:$B,"<"&DATE(2024,3,1)) -> 0 | E8: =SUMIFS('Income Log'!$E:$E,'Income Log'!$D:$D,"Rental Income",'Income Log'!$B:$B,">="&DATE(2024,3,1),'Income Log'!$B:$B,"<"&DATE(2024,4,1)) -> 0 | F8: =SUMIFS('Income Log'!$E:$E,'Income Log'!$D:$D,"Rental Income",'Income Log'!$B:$B,">="&DATE(2024,4,1),'Income Log'!$B:$B,"<"&DATE(2024,5,1)) -> 0 | G8: =SUMIFS('Income Log'!$E:$E,'Income Log'!$D:$D,"Rental Income",'Income Log'!$B:$B,">="&DATE(2024,5,1),'Income Log'!$B:$B,"<"&DATE(2024,6,1)) -> 0 | H8: =SUMIFS('Income Log'!$E:$E,'Income Log'!$D:$D,"Rental Income",'Income Log'!$B:$B,">="&DATE(2024,6,1),'Income Log'!$B:$B,"<"&DATE(2024,7,1)) -> 0 | I8: =SUMIFS('Income Log'!$E:$E,'Income Log'!$D:$D,"Rental Income",'Income Log'!$B:$B,">="&DATE(2024,7,1),'Income Log'!$B:$B,"<"&DATE(2024,8,1)) -> 0 | J8: =SUMIFS('Income Log'!$E:$E,'Income Log'!$D:$D,"Rental Income",'Income Log'!$B:$B,">="&DATE(2024,8,1),'Income Log'!$B:$B,"<"&DATE(2024,9,1)) -> 0 | K8: =SUMIFS('Income Log'!$E:$E,'Income Log'!$D:$D,"Rental Income",'Income Log'!$B:$B,">="&DATE(2024,9,1),'Income Log'!$B:$B,"<"&DATE(2024,10,1)) -> 0 | L8: =SUMIFS('Income Log'!$E:$E,'Income Log'!$D:$D,"Rental Income",'Income Log'!$B:$B,">="&DATE(2024,10,1),'Income Log'!$B:$B,"<"&DATE(2024,11,1)) -> 0 | M8: =SUMIFS('Income Log'!$E:$E,'Income Log'!$D:$D,"Rental Income",'Income Log'!$B:$B,">="&DATE(2024,11,1),'Income Log'!$B:$B,"<"&DATE(2024,12,1)) -> 0 | N8: =SUMIFS('Income Log'!$E:$E,'Income Log'!$D:$D,"Rental Income",'Income Log'!$B:$B,">="&DATE(2024,12,1),'Income Log'!$B:$B,"<"&DATE(2025,1,1)) -> 0 | O8: =SUM(C8:N8) -> 0
B9: Dividends | C9: =SUMIFS('Income Log'!$E:$E,'Income Log'!$D:$D,"Dividends",'Income Log'!$B:$B,">="&DATE(2024,1,1),'Income Log'!$B:$B,"<"&DATE(2024,2,1)) -> 420 | D9: =SUMIFS('Income Log'!$E:$E,'Income Log'!$D:$D,"Dividends",'Income Log'!$B:$B,">="&DATE(2024,2,1),'Income Log'!$B:$B,"<"&DATE(2024,3,1)) -> 0 | E9: =SUMIFS('Income Log'!$E:$E,'Income Log'!$D:$D,"Dividends",'Income Log'!$B:$B,">="&DATE(2024,3,1),'Income Log'!$B:$B,"<"&DATE(2024,4,1)) -> 0 | F9: =SUMIFS('Income Log'!$E:$E,'Income Log'!$D:$D,"Dividends",'Income Log'!$B:$B,">="&DATE(2024,4,1),'Income Log'!$B:$B,"<"&DATE(2024,5,1)) -> 0 | G9: =SUMIFS('Income Log'!$E:$E,'Income Log'!$D:$D,"Dividends",'Income Log'!$B:$B,">="&DATE(2024,5,1),'Income Log'!$B:$B,"<"&DATE(2024,6,1)) -> 0 | H9: =SUMIFS('Income Log'!$E:$E,'Income Log'!$D:$D,"Dividends",'Income Log'!$B:$B,">="&DATE(2024,6,1),'Income Log'!$B:$B,"<"&DATE(2024,7,1)) -> 0 | I9: =SUMIFS('Income Log'!$E:$E,'Income Log'!$D:$D,"Dividends",'Income Log'!$B:$B,">="&DATE(2024,7,1),'Income Log'!$B:$B,"<"&DATE(2024,8,1)) -> 0 | J9: =SUMIFS('Income Log'!$E:$E,'Income Log'!$D:$D,"Dividends",'Income Log'!$B:$B,">="&DATE(2024,8,1),'Income Log'!$B:$B,"<"&DATE(2024,9,1)) -> 0 | K9: =SUMIFS('Income Log'!$E:$E,'Income Log'!$D:$D,"Dividends",'Income Log'!$B:$B,">="&DATE(2024,9,1),'Income Log'!$B:$B,"<"&DATE(2024,10,1)) -> 0 | L9: =SUMIFS('Income Log'!$E:$E,'Income Log'!$D:$D,"Dividends",'Income Log'!$B:$B,">="&DATE(2024,10,1),'Income Log'!$B:$B,"<"&DATE(2024,11,1)) -> 0 | M9: =SUMIFS('Income Log'!$E:$E,'Income Log'!$D:$D,"Dividends",'Income Log'!$B:$B,">="&DATE(2024,11,1),'Income Log'!$B:$B,"<"&DATE(2024,12,1)) -> 0 | N9: =SUMIFS('Income Log'!$E:$E,'Income Log'!$D:$D,"Dividends",'Income Log'!$B:$B,">="&DATE(2024,12,1),'Income Log'!$B:$B,"<"&DATE(2025,1,1)) -> 0 | O9: =SUM(C9:N9) -> 420
B10: Bonus | C10: =SUMIFS('Income Log'!$E:$E,'Income Log'!$D:$D,"Bonus",'Income Log'!$B:$B,">="&DATE(2024,1,1),'Income Log'!$B:$B,"<"&DATE(2024,2,1)) -> 0 | D10: =SUMIFS('Income Log'!$E:$E,'Income Log'!$D:$D,"Bonus",'Income Log'!$B:$B,">="&DATE(2024,2,1),'Income Log'!$B:$B,"<"&DATE(2024,3,1)) -> 0 | E10: =SUMIFS('Income Log'!$E:$E,'Income Log'!$D:$D,"Bonus",'Income Log'!$B:$B,">="&DATE(2024,3,1),'Income Log'!$B:$B,"<"&DATE(2024,4,1)) -> 15000 | F10: =SUMIFS('Income Log'!$E:$E,'Income Log'!$D:$D,"Bonus",'Income Log'!$B:$B,">="&DATE(2024,4,1),'Income Log'!$B:$B,"<"&DATE(2024,5,1)) -> 0 | G10: =SUMIFS('Income Log'!$E:$E,'Income Log'!$D:$D,"Bonus",'Income Log'!$B:$B,">="&DATE(2024,5,1),'Income Log'!$B:$B,"<"&DATE(2024,6,1)) -> 0 | H10: =SUMIFS('Income Log'!$E:$E,'Income Log'!$D:$D,"Bonus",'Income Log'!$B:$B,">="&DATE(2024,6,1),'Income Log'!$B:$B,"<"&DATE(2024,7,1)) -> 0 | I10: =SUMIFS('Income Log'!$E:$E,'Income Log'!$D:$D,"Bonus",'Income Log'!$B:$B,">="&DATE(2024,7,1),'Income Log'!$B:$B,"<"&DATE(2024,8,1)) -> 0 | J10: =SUMIFS('Income Log'!$E:$E,'Income Log'!$D:$D,"Bonus",'Income Log'!$B:$B,">="&DATE(2024,8,1),'Income Log'!$B:$B,"<"&DATE(2024,9,1)) -> 0 | K10: =SUMIFS('Income Log'!$E:$E,'Income Log'!$D:$D,"Bonus",'Income Log'!$B:$B,">="&DATE(2024,9,1),'Income Log'!$B:$B,"<"&DATE(2024,10,1)) -> 0 | L10: =SUMIFS('Income Log'!$E:$E,'Income Log'!$D:$D,"Bonus",'Income Log'!$B:$B,">="&DATE(2024,10,1),'Income Log'!$B:$B,"<"&DATE(2024,11,1)) -> 0 | M10: =SUMIFS('Income Log'!$E:$E,'Income Log'!$D:$D,"Bonus",'Income Log'!$B:$B,">="&DATE(2024,11,1),'Income Log'!$B:$B,"<"&DATE(2024,12,1)) -> 0 | N10: =SUMIFS('Income Log'!$E:$E,'Income Log'!$D:$D,"Bonus",'Income Log'!$B:$B,">="&DATE(2024,12,1),'Income Log'!$B:$B,"<"&DATE(2025,1,1)) -> 0 | O10: =SUM(C10:N10) -> 15000
B11: Other Income | C11: =SUMIFS('Income Log'!$E:$E,'Income Log'!$D:$D,"Other Income",'Income Log'!$B:$B,">="&DATE(2024,1,1),'Income Log'!$B:$B,"<"&DATE(2024,2,1)) -> 0 | D11: =SUMIFS('Income Log'!$E:$E,'Income Log'!$D:$D,"Other Income",'Income Log'!$B:$B,">="&DATE(2024,2,1),'Income Log'!$B:$B,"<"&DATE(2024,3,1)) -> 0 | E11: =SUMIFS('Income Log'!$E:$E,'Income Log'!$D:$D,"Other Income",'Income Log'!$B:$B,">="&DATE(2024,3,1),'Income Log'!$B:$B,"<"&DATE(2024,4,1)) -> 0 | F11: =SUMIFS('Income Log'!$E:$E,'Income Log'!$D:$D,"Other Income",'Income Log'!$B:$B,">="&DATE(2024,4,1),'Income Log'!$B:$B,"<"&DATE(2024,5,1)) -> 0 | G11: =SUMIFS('Income Log'!$E:$E,'Income Log'!$D:$D,"Other Income",'Income Log'!$B:$B,">="&DATE(2024,5,1),'Income Log'!$B:$B,"<"&DATE(2024,6,1)) -> 0 | H11: =SUMIFS('Income Log'!$E:$E,'Income Log'!$D:$D,"Other Income",'Income Log'!$B:$B,">="&DATE(2024,6,1),'Income Log'!$B:$B,"<"&DATE(2024,7,1)) -> 0 | I11: =SUMIFS('Income Log'!$E:$E,'Income Log'!$D:$D,"Other Income",'Income Log'!$B:$B,">="&DATE(2024,7,1),'Income Log'!$B:$B,"<"&DATE(2024,8,1)) -> 0 | J11: =SUMIFS('Income Log'!$E:$E,'Income Log'!$D:$D,"Other Income",'Income Log'!$B:$B,">="&DATE(2024,8,1),'Income Log'!$B:$B,"<"&DATE(2024,9,1)) -> 0 | K11: =SUMIFS('Income Log'!$E:$E,'Income Log'!$D:$D,"Other Income",'Income Log'!$B:$B,">="&DATE(2024,9,1),'Income Log'!$B:$B,"<"&DATE(2024,10,1)) -> 0 | L11: =SUMIFS('Income Log'!$E:$E,'Income Log'!$D:$D,"Other Income",'Income Log'!$B:$B,">="&DATE(2024,10,1),'Income Log'!$B:$B,"<"&DATE(2024,11,1)) -> 0 | M11: =SUMIFS('Income Log'!$E:$E,'Income Log'!$D:$D,"Other Income",'Income Log'!$B:$B,">="&DATE(2024,11,1),'Income Log'!$B:$B,"<"&DATE(2024,12,1)) -> 0 | N11: =SUMIFS('Income Log'!$E:$E,'Income Log'!$D:$D,"Other Income",'Income Log'!$B:$B,">="&DATE(2024,12,1),'Income Log'!$B:$B,"<"&DATE(2025,1,1)) -> 0 | O11: =SUM(C11:N11) -> 0
B12: TOTAL INCOME | C12: =SUM(C6:C11) -> 88920 | D12: =SUM(D6:D11) -> 93000 | E12: =SUM(E6:E11) -> 100000 | F12: =SUM(F6:F11) -> 0 | G12: =SUM(G6:G11) -> 0 | H12: =SUM(H6:H11) -> 0 | I12: =SUM(I6:I11) -> 0 | J12: =SUM(J6:J11) -> 0 | ... O12: =SUM(O6:O11) -> 281920
B14: EXPENSES - add rows to Expense Log to update
B15: Category | C15: Jan | D15: Feb | E15: Mar | F15: Apr | G15: May | H15: Jun | I15: Jul | J15: Aug | K15: Sep | L15: Oct | M15: Nov | N15: Dec | O15: Annual Total
B16: Housing | C16: =SUMIFS('Expense Log'!$E:$E,'Expense Log'!$D:$D,"Housing",'Expense Log'!$B:$B,">="&DATE(2024,1,1),'Expense Log'!$B:$B,"<"&DATE(2024,2,1)) -> 18000 | D16: =SUMIFS('Expense Log'!$E:$E,'Expense Log'!$D:$D,"Housing",'Expense Log'!$B:$B,">="&DATE(2024,2,1),'Expense Log'!$B:$B,"<"&DATE(2024,3,1)) -> 18000 | E16: =SUMIFS('Expense Log'!$E:$E,'Expense Log'!$D:$D,"Housing",'Expense Log'!$B:$B,">="&DATE(2024,3,1),'Expense Log'!$B:$B,"<"&DATE(2024,4,1)) -> 18000 | F16: =SUMIFS('Expense Log'!$E:$E,'Expense Log'!$D:$D,"Housing",'Expense Log'!$B:$B,">="&DATE(2024,4,1),'Expense Log'!$B:$B,"<"&DATE(2024,5,1)) -> 0 | G16: =SUMIFS('Expense Log'!$E:$E,'Expense Log'!$D:$D,"Housing",'Expense Log'!$B:$B,">="&DATE(2024,5,1),'Expense Log'!$B:$B,"<"&DATE(2024,6,1)) -> 0 | H16: =SUMIFS('Expense Log'!$E:$E,'Expense Log'!$D:$D,"Housing",'Expense Log'!$B:$B,">="&DATE(2024,6,1),'Expense Log'!$B:$B,"<"&DATE(2024,7,1)) -> 0 | I16: =SUMIFS('Expense Log'!$E:$E,'Expense Log'!$D:$D,"Housing",'Expense Log'!$B:$B,">="&DATE(2024,7,1),'Expense Log'!$B:$B,"<"&DATE(2024,8,1)) -> 0 | J16: =SUMIFS('Expense Log'!$E:$E,'Expense Log'!$D:$D,"Housing",'Expense Log'!$B:$B,">="&DATE(2024,8,1),'Expense Log'!$B:$B,"<"&DATE(2024,9,1)) -> 0 | K16: =SUMIFS('Expense Log'!$E:$E,'Expense Log'!$D:$D,"Housing",'Expense Log'!$B:$B,">="&DATE(2024,9,1),'Expense Log'!$B:$B,"<"&DATE(2024,10,1)) -> 0 | L16: =SUMIFS('Expense Log'!$E:$E,'Expense Log'!$D:$D,"Housing",'Expense Log'!$B:$B,">="&DATE(2024,10,1),'Expense Log'!$B:$B,"<"&DATE(2024,11,1)) -> 0 | M16: =SUMIFS('Expense Log'!$E:$E,'Expense Log'!$D:$D,"Housing",'Expense Log'!$B:$B,">="&DATE(2024,11,1),'Expense Log'!$B:$B,"<"&DATE(2024,12,1)) -> 0 | N16: =SUMIFS('Expense Log'!$E:$E,'Expense Log'!$D:$D,"Housing",'Expense Log'!$B:$B,">="&DATE(2024,12,1),'Expense Log'!$B:$B,"<"&DATE(2025,1,1)) -> 0 | O16: =SUM(C16:N16) -> 54000
B17: Food and Groceries | C17: =SUMIFS('Expense Log'!$E:$E,'Expense Log'!$D:$D,"Food and Groceries",'Expense Log'!$B:$B,">="&DATE(2024,1,1),'Expense Log'!$B:$B,"<"&DATE(2024,2,1)) -> 3650 | D17: =SUMIFS('Expense Log'!$E:$E,'Expense Log'!$D:$D,"Food and Groceries",'Expense Log'!$B:$B,">="&DATE(2024,2,1),'Expense Log'!$B:$B,"<"&DATE(2024,3,1)) -> 2800 | E17: =SUMIFS('Expense Log'!$E:$E,'Expense Log'!$D:$D,"Food and Groceries",'Expense Log'!$B:$B,">="&DATE(2024,3,1),'Expense Log'!$B:$B,"<"&DATE(2024,4,1)) -> 0 | F17: =SUMIFS('Expense Log'!$E:$E,'Expense Log'!$D:$D,"Food and Groceries",'Expense Log'!$B:$B,">="&DATE(2024,4,1),'Expense Log'!$B:$B,"<"&DATE(2024,5,1)) -> 0 | G17: =SUMIFS('Expense Log'!$E:$E,'Expense Log'!$D:$D,"Food and Groceries",'Expense Log'!$B:$B,">="&DATE(2024,5,1),'Expense Log'!$B:$B,"<"&DATE(2024,6,1)) -> 0 | H17: =SUMIFS('Expense Log'!$E:$E,'Expense Log'!$D:$D,"Food and Groceries",'Expense Log'!$B:$B,">="&DATE(2024,6,1),'Expense Log'!$B:$B,"<"&DATE(2024,7,1)) -> 0 | I17: =SUMIFS('Expense Log'!$E:$E,'Expense Log'!$D:$D,"Food and Groceries",'Expense Log'!$B:$B,">="&DATE(2024,7,1),'Expense Log'!$B:$B,"<"&DATE(2024,8,1)) -> 0 | J17: =SUMIFS('Expense Log'!$E:$E,'Expense Log'!$D:$D,"Food and Groceries",'Expense Log'!$B:$B,">="&DATE(2024,8,1),'Expense Log'!$B:$B,"<"&DATE(2024,9,1)) -> 0 | K17: =SUMIFS('Expense Log'!$E:$E,'Expense Log'!$D:$D,"Food and Groceries",'Expense Log'!$B:$B,">="&DATE(2024,9,1),'Expense Log'!$B:$B,"<"&DATE(2024,10,1)) -> 0 | L17: =SUMIFS('Expense Log'!$E:$E,'Expense Log'!$D:$D,"Food and Groceries",'Expense Log'!$B:$B,">="&DATE(2024,10,1),'Expense Log'!$B:$B,"<"&DATE(2024,11,1)) -> 0 | M17: =SUMIFS('Expense Log'!$E:$E,'Expense Log'!$D:$D,"Food and Groceries",'Expense Log'!$B:$B,">="&DATE(2024,11,1),'Expense Log'!$B:$B,"<"&DATE(2024,12,1)) -> 0 | N17: =SUMIFS('Expense Log'!$E:$E,'Expense Log'!$D:$D,"Food and Groceries",'Expense Log'!$B:$B,">="&DATE(2024,12,1),'Expense Log'!$B:$B,"<"&DATE(2025,1,1)) -> 0 | O17: =SUM(C17:N17) -> 6450
B18: Transport | C18: =SUMIFS('Expense Log'!$E:$E,'Expense Log'!$D:$D,"Transport",'Expense Log'!$B:$B,">="&DATE(2024,1,1),'Expense Log'!$B:$B,"<"&DATE(2024,2,1)) -> 1600 | D18: =SUMIFS('Expense Log'!$E:$E,'Expense Log'!$D:$D,"Transport",'Expense Log'!$B:$B,">="&DATE(2024,2,1),'Expense Log'!$B:$B,"<"&DATE(2024,3,1)) -> 0 | E18: =SUMIFS('Expense Log'!$E:$E,'Expense Log'!$D:$D,"Transport",'Expense Log'!$B:$B,">="&DATE(2024,3,1),'Expense Log'!$B:$B,"<"&DATE(2024,4,1)) -> 0 | F18: =SUMIFS('Expense Log'!$E:$E,'Expense Log'!$D:$D,"Transport",'Expense Log'!$B:$B,">="&DATE(2024,4,1),'Expense Log'!$B:$B,"<"&DATE(2024,5,1)) -> 0 | G18: =SUMIFS('Expense Log'!$E:$E,'Expense Log'!$D:$D,"Transport",'Expense Log'!$B:$B,">="&DATE(2024,5,1),'Expense Log'!$B:$B,"<"&DATE(2024,6,1)) -> 0 | H18: =SUMIFS('Expense Log'!$E:$E,'Expense Log'!$D:$D,"Transport",'Expense Log'!$B:$B,">="&DATE(2024,6,1),'Expense Log'!$B:$B,"<"&DATE(2024,7,1)) -> 0 | I18: =SUMIFS('Expense Log'!$E:$E,'Expense Log'!$D:$D,"Transport",'Expense Log'!$B:$B,">="&DATE(2024,7,1),'Expense Log'!$B:$B,"<"&DATE(2024,8,1)) -> 0 | J18: =SUMIFS('Expense Log'!$E:$E,'Expense Log'!$D:$D,"Transport",'Expense Log'!$B:$B,">="&DATE(2024,8,1),'Expense Log'!$B:$B,"<"&DATE(2024,9,1)) -> 0 | K18: =SUMIFS('Expense Log'!$E:$E,'Expense Log'!$D:$D,"Transport",'Expense Log'!$B:$B,">="&DATE(2024,9,1),'Expense Log'!$B:$B,"<"&DATE(2024,10,1)) -> 0 | L18: =SUMIFS('Expense Log'!$E:$E,'Expense Log'!$D:$D,"Transport",'Expense Log'!$B:$B,">="&DATE(2024,10,1),'Expense Log'!$B:$B,"<"&DATE(2024,11,1)) -> 0 | M18: =SUMIFS('Expense Log'!$E:$E,'Expense Log'!$D:$D,"Transport",'Expense Log'!$B:$B,">="&DATE(2024,11,1),'Expense Log'!$B:$B,"<"&DATE(2024,12,1)) -> 0 | N18: =SUMIFS('Expense Log'!$E:$E,'Expense Log'!$D:$D,"Transport",'Expense Log'!$B:$B,">="&DATE(2024,12,1),'Expense Log'!$B:$B,"<"&DATE(2025,1,1)) -> 0 | O18: =SUM(C18:N18) -> 1600
B19: Health and Medical | C19: =SUMIFS('Expense Log'!$E:$E,'Expense Log'!$D:$D,"Health and Medical",'Expense Log'!$B:$B,">="&DATE(2024,1,1),'Expense Log'!$B:$B,"<"&DATE(2024,2,1)) -> 700 | D19: =SUMIFS('Expense Log'!$E:$E,'Expense Log'!$D:$D,"Health and Medical",'Expense Log'!$B:$B,">="&DATE(2024,2,1),'Expense Log'!$B:$B,"<"&DATE(2024,3,1)) -> 0 | E19: =SUMIFS('Expense Log'!$E:$E,'Expense Log'!$D:$D,"Health and Medical",'Expense Log'!$B:$B,">="&DATE(2024,3,1),'Expense Log'!$B:$B,"<"&DATE(2024,4,1)) -> 0 | F19: =SUMIFS('Expense Log'!$E:$E,'Expense Log'!$D:$D,"Health and Medical",'Expense Log'!$B:$B,">="&DATE(2024,4,1),'Expense Log'!$B:$B,"<"&DATE(2024,5,1)) -> 0 | G19: =SUMIFS('Expense Log'!$E:$E,'Expense Log'!$D:$D,"Health and Medical",'Expense Log'!$B:$B,">="&DATE(2024,5,1),'Expense Log'!$B:$B,"<"&DATE(2024,6,1)) -> 0 | H19: =SUMIFS('Expense Log'!$E:$E,'Expense Log'!$D:$D,"Health and Medical",'Expense Log'!$B:$B,">="&DATE(2024,6,1),'Expense Log'!$B:$B,"<"&DATE(2024,7,1)) -> 0 | I19: =SUMIFS('Expense Log'!$E:$E,'Expense Log'!$D:$D,"Health and Medical",'Expense Log'!$B:$B,">="&DATE(2024,7,1),'Expense Log'!$B:$B,"<"&DATE(2024,8,1)) -> 0 | J19: =SUMIFS('Expense Log'!$E:$E,'Expense Log'!$D:$D,"Health and Medical",'Expense Log'!$B:$B,">="&DATE(2024,8,1),'Expense Log'!$B:$B,"<"&DATE(2024,9,1)) -> 0 | K19: =SUMIFS('Expense Log'!$E:$E,'Expense Log'!$D:$D,"Health and Medical",'Expense Log'!$B:$B,">="&DATE(2024,9,1),'Expense Log'!$B:$B,"<"&DATE(2024,10,1)) -> 0 | L19: =SUMIFS('Expense Log'!$E:$E,'Expense Log'!$D:$D,"Health and Medical",'Expense Log'!$B:$B,">="&DATE(2024,10,1),'Expense Log'!$B:$B,"<"&DATE(2024,11,1)) -> 0 | M19: =SUMIFS('Expense Log'!$E:$E,'Expense Log'!$D:$D,"Health and Medical",'Expense Log'!$B:$B,">="&DATE(2024,11,1),'Expense Log'!$B:$B,"<"&DATE(2024,12,1)) -> 0 | N19: =SUMIFS('Expense Log'!$E:$E,'Expense Log'!$D:$D,"Health and Medical",'Expense Log'!$B:$B,">="&DATE(2024,12,1),'Expense Log'!$B:$B,"<"&DATE(2025,1,1)) -> 0 | O19: =SUM(C19:N19) -> 700
B20: Education | C20: =SUMIFS('Expense Log'!$E:$E,'Expense Log'!$D:$D,"Education",'Expense Log'!$B:$B,">="&DATE(2024,1,1),'Expense Log'!$B:$B,"<"&DATE(2024,2,1)) -> 499 | D20: =SUMIFS('Expense Log'!$E:$E,'Expense Log'!$D:$D,"Education",'Expense Log'!$B:$B,">="&DATE(2024,2,1),'Expense Log'!$B:$B,"<"&DATE(2024,3,1)) -> 0 | E20: =SUMIFS('Expense Log'!$E:$E,'Expense Log'!$D:$D,"Education",'Expense Log'!$B:$B,">="&DATE(2024,3,1),'Expense Log'!$B:$B,"<"&DATE(2024,4,1)) -> 0 | F20: =SUMIFS('Expense Log'!$E:$E,'Expense Log'!$D:$D,"Education",'Expense Log'!$B:$B,">="&DATE(2024,4,1),'Expense Log'!$B:$B,"<"&DATE(2024,5,1)) -> 0 | G20: =SUMIFS('Expense Log'!$E:$E,'Expense Log'!$D:$D,"Education",'Expense Log'!$B:$B,">="&DATE(2024,5,1),'Expense Log'!$B:$B,"<"&DATE(2024,6,1)) -> 0 | H20: =SUMIFS('Expense Log'!$E:$E,'Expense Log'!$D:$D,"Education",'Expense Log'!$B:$B,">="&DATE(2024,6,1),'Expense Log'!$B:$B,"<"&DATE(2024,7,1)) -> 0 | I20: =SUMIFS('Expense Log'!$E:$E,'Expense Log'!$D:$D,"Education",'Expense Log'!$B:$B,">="&DATE(2024,7,1),'Expense Log'!$B:$B,"<"&DATE(2024,8,1)) -> 0 | J20: =SUMIFS('Expense Log'!$E:$E,'Expense Log'!$D:$D,"Education",'Expense Log'!$B:$B,">="&DATE(2024,8,1),'Expense Log'!$B:$B,"<"&DATE(2024,9,1)) -> 0 | K20: =SUMIFS('Expense Log'!$E:$E,'Expense Log'!$D:$D,"Education",'Expense Log'!$B:$B,">="&DATE(2024,9,1),'Expense Log'!$B:$B,"<"&DATE(2024,10,1)) -> 0 | L20: =SUMIFS('Expense Log'!$E:$E,'Expense Log'!$D:$D,"Education",'Expense Log'!$B:$B,">="&DATE(2024,10,1),'Expense Log'!$B:$B,"<"&DATE(2024,11,1)) -> 0 | M20: =SUMIFS('Expense Log'!$E:$E,'Expense Log'!$D:$D,"Education",'Expense Log'!$B:$B,">="&DATE(2024,11,1),'Expense Log'!$B:$B,"<"&DATE(2024,12,1)) -> 0 | N20: =SUMIFS('Expense Log'!$E:$E,'Expense Log'!$D:$D,"Education",'Expense Log'!$B:$B,">="&DATE(2024,12,1),'Expense Log'!$B:$B,"<"&DATE(2025,1,1)) -> 0 | O20: =SUM(C20:N20) -> 499
B21: Shopping | C21: =SUMIFS('Expense Log'!$E:$E,'Expense Log'!$D:$D,"Shopping",'Expense Log'!$B:$B,">="&DATE(2024,1,1),'Expense Log'!$B:$B,"<"&DATE(2024,2,1)) -> 0 | D21: =SUMIFS('Expense Log'!$E:$E,'Expense Log'!$D:$D,"Shopping",'Expense Log'!$B:$B,">="&DATE(2024,2,1),'Expense Log'!$B:$B,"<"&DATE(2024,3,1)) -> 1200 | E21: =SUMIFS('Expense Log'!$E:$E,'Expense Log'!$D:$D,"Shopping",'Expense Log'!$B:$B,">="&DATE(2024,3,1),'Expense Log'!$B:$B,"<"&DATE(2024,4,1)) -> 0 | F21: =SUMIFS('Expense Log'!$E:$E,'Expense Log'!$D:$D,"Shopping",'Expense Log'!$B:$B,">="&DATE(2024,4,1),'Expense Log'!$B:$B,"<"&DATE(2024,5,1)) -> 0 | G21: =SUMIFS('Expense Log'!$E:$E,'Expense Log'!$D:$D,"Shopping",'Expense Log'!$B:$B,">="&DATE(2024,5,1),'Expense Log'!$B:$B,"<"&DATE(2024,6,1)) -> 0 | H21: =SUMIFS('Expense Log'!$E:$E,'Expense Log'!$D:$D,"Shopping",'Expense Log'!$B:$B,">="&DATE(2024,6,1),'Expense Log'!$B:$B,"<"&DATE(2024,7,1)) -> 0 | I21: =SUMIFS('Expense Log'!$E:$E,'Expense Log'!$D:$D,"Shopping",'Expense Log'!$B:$B,">="&DATE(2024,7,1),'Expense Log'!$B:$B,"<"&DATE(2024,8,1)) -> 0 | J21: =SUMIFS('Expense Log'!$E:$E,'Expense Log'!$D:$D,"Shopping",'Expense Log'!$B:$B,">="&DATE(2024,8,1),'Expense Log'!$B:$B,"<"&DATE(2024,9,1)) -> 0 | K21: =SUMIFS('Expense Log'!$E:$E,'Expense Log'!$D:$D,"Shopping",'Expense Log'!$B:$B,">="&DATE(2024,9,1),'Expense Log'!$B:$B,"<"&DATE(2024,10,1)) -> 0 | L21: =SUMIFS('Expense Log'!$E:$E,'Expense Log'!$D:$D,"Shopping",'Expense Log'!$B:$B,">="&DATE(2024,10,1),'Expense Log'!$B:$B,"<"&DATE(2024,11,1)) -> 0 | M21: =SUMIFS('Expense Log'!$E:$E,'Expense Log'!$D:$D,"Shopping",'Expense Log'!$B:$B,">="&DATE(2024,11,1),'Expense Log'!$B:$B,"<"&DATE(2024,12,1)) -> 0 | N21: =SUMIFS('Expense Log'!$E:$E,'Expense Log'!$D:$D,"Shopping",'Expense Log'!$B:$B,">="&DATE(2024,12,1),'Expense Log'!$B:$B,"<"&DATE(2025,1,1)) -> 0 | O21: =SUM(C21:N21) -> 1200
B22: Subscriptions | C22: =SUMIFS('Expense Log'!$E:$E,'Expense Log'!$D:$D,"Subscriptions",'Expense Log'!$B:$B,">="&DATE(2024,1,1),'Expense Log'!$B:$B,"<"&DATE(2024,2,1)) -> 499 | D22: =SUMIFS('Expense Log'!$E:$E,'Expense Log'!$D:$D,"Subscriptions",'Expense Log'!$B:$B,">="&DATE(2024,2,1),'Expense Log'!$B:$B,"<"&DATE(2024,3,1)) -> 0 | E22: =SUMIFS('Expense Log'!$E:$E,'Expense Log'!$D:$D,"Subscriptions",'Expense Log'!$B:$B,">="&DATE(2024,3,1),'Expense Log'!$B:$B,"<"&DATE(2024,4,1)) -> 0 | F22: =SUMIFS('Expense Log'!$E:$E,'Expense Log'!$D:$D,"Subscriptions",'Expense Log'!$B:$B,">="&DATE(2024,4,1),'Expense Log'!$B:$B,"<"&DATE(2024,5,1)) -> 0 | G22: =SUMIFS('Expense Log'!$E:$E,'Expense Log'!$D:$D,"Subscriptions",'Expense Log'!$B:$B,">="&DATE(2024,5,1),'Expense Log'!$B:$B,"<"&DATE(2024,6,1)) -> 0 | H22: =SUMIFS('Expense Log'!$E:$E,'Expense Log'!$D:$D,"Subscriptions",'Expense Log'!$B:$B,">="&DATE(2024,6,1),'Expense Log'!$B:$B,"<"&DATE(2024,7,1)) -> 0 | I22: =SUMIFS('Expense Log'!$E:$E,'Expense Log'!$D:$D,"Subscriptions",'Expense Log'!$B:$B,">="&DATE(2024,7,1),'Expense Log'!$B:$B,"<"&DATE(2024,8,1)) -> 0 | J22: =SUMIFS('Expense Log'!$E:$E,'Expense Log'!$D:$D,"Subscriptions",'Expense Log'!$B:$B,">="&DATE(2024,8,1),'Expense Log'!$B:$B,"<"&DATE(2024,9,1)) -> 0 | K22: =SUMIFS('Expense Log'!$E:$E,'Expense Log'!$D:$D,"Subscriptions",'Expense Log'!$B:$B,">="&DATE(2024,9,1),'Expense Log'!$B:$B,"<"&DATE(2024,10,1)) -> 0 | L22: =SUMIFS('Expense Log'!$E:$E,'Expense Log'!$D:$D,"Subscriptions",'Expense Log'!$B:$B,">="&DATE(2024,10,1),'Expense Log'!$B:$B,"<"&DATE(2024,11,1)) -> 0 | M22: =SUMIFS('Expense Log'!$E:$E,'Expense Log'!$D:$D,"Subscriptions",'Expense Log'!$B:$B,">="&DATE(2024,11,1),'Expense Log'!$B:$B,"<"&DATE(2024,12,1)) -> 0 | N22: =SUMIFS('Expense Log'!$E:$E,'Expense Log'!$D:$D,"Subscriptions",'Expense Log'!$B:$B,">="&DATE(2024,12,1),'Expense Log'!$B:$B,"<"&DATE(2025,1,1)) -> 0 | O22: =SUM(C22:N22) -> 499
B23: Entertainment | C23: =SUMIFS('Expense Log'!$E:$E,'Expense Log'!$D:$D,"Entertainment",'Expense Log'!$B:$B,">="&DATE(2024,1,1),'Expense Log'!$B:$B,"<"&DATE(2024,2,1)) -> 600 | D23: =SUMIFS('Expense Log'!$E:$E,'Expense Log'!$D:$D,"Entertainment",'Expense Log'!$B:$B,">="&DATE(2024,2,1),'Expense Log'!$B:$B,"<"&DATE(2024,3,1)) -> 0 | E23: =SUMIFS('Expense Log'!$E:$E,'Expense Log'!$D:$D,"Entertainment",'Expense Log'!$B:$B,">="&DATE(2024,3,1),'Expense Log'!$B:$B,"<"&DATE(2024,4,1)) -> 0 | F23: =SUMIFS('Expense Log'!$E:$E,'Expense Log'!$D:$D,"Entertainment",'Expense Log'!$B:$B,">="&DATE(2024,4,1),'Expense Log'!$B:$B,"<"&DATE(2024,5,1)) -> 0 | G23: =SUMIFS('Expense Log'!$E:$E,'Expense Log'!$D:$D,"Entertainment",'Expense Log'!$B:$B,">="&DATE(2024,5,1),'Expense Log'!$B:$B,"<"&DATE(2024,6,1)) -> 0 | H23: =SUMIFS('Expense Log'!$E:$E,'Expense Log'!$D:$D,"Entertainment",'Expense Log'!$B:$B,">="&DATE(2024,6,1),'Expense Log'!$B:$B,"<"&DATE(2024,7,1)) -> 0 | I23: =SUMIFS('Expense Log'!$E:$E,'Expense Log'!$D:$D,"Entertainment",'Expense Log'!$B:$B,">="&DATE(2024,7,1),'Expense Log'!$B:$B,"<"&DATE(2024,8,1)) -> 0 | J23: =SUMIFS('Expense Log'!$E:$E,'Expense Log'!$D:$D,"Entertainment",'Expense Log'!$B:$B,">="&DATE(2024,8,1),'Expense Log'!$B:$B,"<"&DATE(2024,9,1)) -> 0 | K23: =SUMIFS('Expense Log'!$E:$E,'Expense Log'!$D:$D,"Entertainment",'Expense Log'!$B:$B,">="&DATE(2024,9,1),'Expense Log'!$B:$B,"<"&DATE(2024,10,1)) -> 0 | L23: =SUMIFS('Expense Log'!$E:$E,'Expense Log'!$D:$D,"Entertainment",'Expense Log'!$B:$B,">="&DATE(2024,10,1),'Expense Log'!$B:$B,"<"&DATE(2024,11,1)) -> 0 | M23: =SUMIFS('Expense Log'!$E:$E,'Expense Log'!$D:$D,"Entertainment",'Expense Log'!$B:$B,">="&DATE(2024,11,1),'Expense Log'!$B:$B,"<"&DATE(2024,12,1)) -> 0 | N23: =SUMIFS('Expense Log'!$E:$E,'Expense Log'!$D:$D,"Entertainment",'Expense Log'!$B:$B,">="&DATE(2024,12,1),'Expense Log'!$B:$B,"<"&DATE(2025,1,1)) -> 0 | O23: =SUM(C23:N23) -> 600
B24: Travel | C24: =SUMIFS('Expense Log'!$E:$E,'Expense Log'!$D:$D,"Travel",'Expense Log'!$B:$B,">="&DATE(2024,1,1),'Expense Log'!$B:$B,"<"&DATE(2024,2,1)) -> 0 | D24: =SUMIFS('Expense Log'!$E:$E,'Expense Log'!$D:$D,"Travel",'Expense Log'!$B:$B,">="&DATE(2024,2,1),'Expense Log'!$B:$B,"<"&DATE(2024,3,1)) -> 0 | E24: =SUMIFS('Expense Log'!$E:$E,'Expense Log'!$D:$D,"Travel",'Expense Log'!$B:$B,">="&DATE(2024,3,1),'Expense Log'!$B:$B,"<"&DATE(2024,4,1)) -> 0 | F24: =SUMIFS('Expense Log'!$E:$E,'Expense Log'!$D:$D,"Travel",'Expense Log'!$B:$B,">="&DATE(2024,4,1),'Expense Log'!$B:$B,"<"&DATE(2024,5,1)) -> 0 | G24: =SUMIFS('Expense Log'!$E:$E,'Expense Log'!$D:$D,"Travel",'Expense Log'!$B:$B,">="&DATE(2024,5,1),'Expense Log'!$B:$B,"<"&DATE(2024,6,1)) -> 0 | H24: =SUMIFS('Expense Log'!$E:$E,'Expense Log'!$D:$D,"Travel",'Expense Log'!$B:$B,">="&DATE(2024,6,1),'Expense Log'!$B:$B,"<"&DATE(2024,7,1)) -> 0 | I24: =SUMIFS('Expense Log'!$E:$E,'Expense Log'!$D:$D,"Travel",'Expense Log'!$B:$B,">="&DATE(2024,7,1),'Expense Log'!$B:$B,"<"&DATE(2024,8,1)) -> 0 | J24: =SUMIFS('Expense Log'!$E:$E,'Expense Log'!$D:$D,"Travel",'Expense Log'!$B:$B,">="&DATE(2024,8,1),'Expense Log'!$B:$B,"<"&DATE(2024,9,1)) -> 0 | K24: =SUMIFS('Expense Log'!$E:$E,'Expense Log'!$D:$D,"Travel",'Expense Log'!$B:$B,">="&DATE(2024,9,1),'Expense Log'!$B:$B,"<"&DATE(2024,10,1)) -> 0 | L24: =SUMIFS('Expense Log'!$E:$E,'Expense Log'!$D:$D,"Travel",'Expense Log'!$B:$B,">="&DATE(2024,10,1),'Expense Log'!$B:$B,"<"&DATE(2024,11,1)) -> 0 | M24: =SUMIFS('Expense Log'!$E:$E,'Expense Log'!$D:$D,"Travel",'Expense Log'!$B:$B,">="&DATE(2024,11,1),'Expense Log'!$B:$B,"<"&DATE(2024,12,1)) -> 0 | N24: =SUMIFS('Expense Log'!$E:$E,'Expense Log'!$D:$D,"Travel",'Expense Log'!$B:$B,">="&DATE(2024,12,1),'Expense Log'!$B:$B,"<"&DATE(2025,1,1)) -> 0 | O24: =SUM(C24:N24) -> 0
B25: Savings and Investments | C25: =SUMIFS('Expense Log'!$E:$E,'Expense Log'!$D:$D,"Savings and Investments",'Expense Log'!$B:$B,">="&DATE(2024,1,1),'Expense Log'!$B:$B,"<"&DATE(2024,2,1)) -> 5000 | D25: =SUMIFS('Expense Log'!$E:$E,'Expense Log'!$D:$D,"Savings and Investments",'Expense Log'!$B:$B,">="&DATE(2024,2,1),'Expense Log'!$B:$B,"<"&DATE(2024,3,1)) -> 3000 | E25: =SUMIFS('Expense Log'!$E:$E,'Expense Log'!$D:$D,"Savings and Investments",'Expense Log'!$B:$B,">="&DATE(2024,3,1),'Expense Log'!$B:$B,"<"&DATE(2024,4,1)) -> 0 | F25: =SUMIFS('Expense Log'!$E:$E,'Expense Log'!$D:$D,"Savings and Investments",'Expense Log'!$B:$B,">="&DATE(2024,4,1),'Expense Log'!$B:$B,"<"&DATE(2024,5,1)) -> 0 | G25: =SUMIFS('Expense Log'!$E:$E,'Expense Log'!$D:$D,"Savings and Investments",'Expense Log'!$B:$B,">="&DATE(2024,5,1),'Expense Log'!$B:$B,"<"&DATE(2024,6,1)) -> 0 | H25: =SUMIFS('Expense Log'!$E:$E,'Expense Log'!$D:$D,"Savings and Investments",'Expense Log'!$B:$B,">="&DATE(2024,6,1),'Expense Log'!$B:$B,"<"&DATE(2024,7,1)) -> 0 | I25: =SUMIFS('Expense Log'!$E:$E,'Expense Log'!$D:$D,"Savings and Investments",'Expense Log'!$B:$B,">="&DATE(2024,7,1),'Expense Log'!$B:$B,"<"&DATE(2024,8,1)) -> 0 | J25: =SUMIFS('Expense Log'!$E:$E,'Expense Log'!$D:$D,"Savings and Investments",'Expense Log'!$B:$B,">="&DATE(2024,8,1),'Expense Log'!$B:$B,"<"&DATE(2024,9,1)) -> 0 | K25: =SUMIFS('Expense Log'!$E:$E,'Expense Log'!$D:$D,"Savings and Investments",'Expense Log'!$B:$B,">="&DATE(2024,9,1),'Expense Log'!$B:$B,"<"&DATE(2024,10,1)) -> 0 | L25: =SUMIFS('Expense Log'!$E:$E,'Expense Log'!$D:$D,"Savings and Investments",'Expense Log'!$B:$B,">="&DATE(2024,10,1),'Expense Log'!$B:$B,"<"&DATE(2024,11,1)) -> 0 | M25: =SUMIFS('Expense Log'!$E:$E,'Expense Log'!$D:$D,"Savings and Investments",'Expense Log'!$B:$B,">="&DATE(2024,11,1),'Expense Log'!$B:$B,"<"&DATE(2024,12,1)) -> 0 | N25: =SUMIFS('Expense Log'!$E:$E,'Expense Log'!$D:$D,"Savings and Investments",'Expense Log'!$B:$B,">="&DATE(2024,12,1),'Expense Log'!$B:$B,"<"&DATE(2025,1,1)) -> 0 | O25: =SUM(C25:N25) -> 8000
B26: Miscellaneous | C26: =SUMIFS('Expense Log'!$E:$E,'Expense Log'!$D:$D,"Miscellaneous",'Expense Log'!$B:$B,">="&DATE(2024,1,1),'Expense Log'!$B:$B,"<"&DATE(2024,2,1)) -> 0 | D26: =SUMIFS('Expense Log'!$E:$E,'Expense Log'!$D:$D,"Miscellaneous",'Expense Log'!$B:$B,">="&DATE(2024,2,1),'Expense Log'!$B:$B,"<"&DATE(2024,3,1)) -> 0 | E26: =SUMIFS('Expense Log'!$E:$E,'Expense Log'!$D:$D,"Miscellaneous",'Expense Log'!$B:$B,">="&DATE(2024,3,1),'Expense Log'!$B:$B,"<"&DATE(2024,4,1)) -> 0 | F26: =SUMIFS('Expense Log'!$E:$E,'Expense Log'!$D:$D,"Miscellaneous",'Expense Log'!$B:$B,">="&DATE(2024,4,1),'Expense Log'!$B:$B,"<"&DATE(2024,5,1)) -> 0 | G26: =SUMIFS('Expense Log'!$E:$E,'Expense Log'!$D:$D,"Miscellaneous",'Expense Log'!$B:$B,">="&DATE(2024,5,1),'Expense Log'!$B:$B,"<"&DATE(2024,6,1)) -> 0 | H26: =SUMIFS('Expense Log'!$E:$E,'Expense Log'!$D:$D,"Miscellaneous",'Expense Log'!$B:$B,">="&DATE(2024,6,1),'Expense Log'!$B:$B,"<"&DATE(2024,7,1)) -> 0 | I26: =SUMIFS('Expense Log'!$E:$E,'Expense Log'!$D:$D,"Miscellaneous",'Expense Log'!$B:$B,">="&DATE(2024,7,1),'Expense Log'!$B:$B,"<"&DATE(2024,8,1)) -> 0 | J26: =SUMIFS('Expense Log'!$E:$E,'Expense Log'!$D:$D,"Miscellaneous",'Expense Log'!$B:$B,">="&DATE(2024,8,1),'Expense Log'!$B:$B,"<"&DATE(2024,9,1)) -> 0 | K26: =SUMIFS('Expense Log'!$E:$E,'Expense Log'!$D:$D,"Miscellaneous",'Expense Log'!$B:$B,">="&DATE(2024,9,1),'Expense Log'!$B:$B,"<"&DATE(2024,10,1)) -> 0 | L26: =SUMIFS('Expense Log'!$E:$E,'Expense Log'!$D:$D,"Miscellaneous",'Expense Log'!$B:$B,">="&DATE(2024,10,1),'Expense Log'!$B:$B,"<"&DATE(2024,11,1)) -> 0 | M26: =SUMIFS('Expense Log'!$E:$E,'Expense Log'!$D:$D,"Miscellaneous",'Expense Log'!$B:$B,">="&DATE(2024,11,1),'Expense Log'!$B:$B,"<"&DATE(2024,12,1)) -> 0 | N26: =SUMIFS('Expense Log'!$E:$E,'Expense Log'!$D:$D,"Miscellaneous",'Expense Log'!$B:$B,">="&DATE(2024,12,1),'Expense Log'!$B:$B,"<"&DATE(2025,1,1)) -> 0 | O26: =SUM(C26:N26) -> 0
B27: TOTAL EXPENSES | C27: =SUM(C16:C26) -> 30548 | D27: =SUM(D16:D26) -> 25000 | E27: =SUM(E16:E26) -> 18000 | F27: =SUM(F16:F26) -> 0 | G27: =SUM(G16:G26) -> 0 | H27: =SUM(H16:H26) -> 0 | I27: =SUM(I16:I26) -> 0 | J27: =SUM(J16:J26) -> 0 | ... O27: =SUM(O16:O26) -> 73548
B29: NET SAVINGS | C29: =C12-C27 -> 58372 | D29: =D12-D27 -> 68000 | E29: =E12-E27 -> 82000 | F29: =F12-F27 -> 0 | G29: =G12-G27 -> 0 | H29: =H12-H27 -> 0 | I29: =I12-I27 -> 0 | J29: =J12-J27 -> 0 | ... O29: =O12-O27 -> 208372
B30: SAVINGS RATE | C30: =IF(C12=0,0,C29/C12) -> 0.65645524 | D30: =IF(D12=0,0,D29/D12) -> 0.7311828 | E30: =IF(E12=0,0,E29/E12) -> 0.82 | F30: =IF(F12=0,0,F29/F12) -> 0 | G30: =IF(G12=0,0,G29/G12) -> 0 | H30: =IF(H12=0,0,H29/H12) -> 0 | I30: =IF(I12=0,0,I29/I12) -> 0 | J30: =IF(J12=0,0,J29/J12) -> 0 | ... O30: =IF(O12=0,0,O29/O12) -> 0.73911748

Sheet Expense Log
B1: EXPENSE LOG - Enter every expense here
B2: Total Expenses Logged: | E2: =SUM(E5:E9999) -> 73548
B3: Date format: 2024-MM-DD | Use dropdown for Category | Amount in numbers only (no symbols or commas)
B4: Date | C4: Description | D4: Category | E4: Amount | F4: Payment Method | G4: Notes
B5: 45292 | C5: Monthly rent | D5: Housing | E5: 18000 | F5: Net Banking | G5: January
B6: 45294 | C6: Swiggy dinner | D6: Food and Groceries | E6: 450 | F6: UPI GPay
B7: 45296 | C7: Metro card recharge | D7: Transport | E7: 500 | F7: UPI GPay | G7: Monthly pass
B8: 45297 | C8: Big Basket groceries | D8: Food and Groceries | E8: 3200 | F8: Credit Card
B9: 45298 | C9: Netflix subscription | D9: Subscriptions | E9: 499 | F9: Auto-Debit
B10: 45301 | C10: Petrol | D10: Transport | E10: 1100 | F10: Debit Card
B11: 45303 | C11: Doctor consultation | D11: Health and Medical | E11: 700 | F11: Cash
B12: 45306 | C12: Udemy Python course | D12: Education | E12: 499 | F12: Credit Card
B13: 45309 | C13: SIP NIFTY 50 | D13: Savings and Investments | E13: 5000 | F13: Auto-Debit | G13: Index fund
B14: 45311 | C14: Movie tickets x2 | D14: Entertainment | E14: 600 | F14: UPI GPay
B15: 45323 | C15: Monthly rent | D15: Housing | E15: 18000 | F15: Net Banking | G15: February
B16: 45326 | C16: Grocery store | D16: Food and Groceries | E16: 2800 | F16: Debit Card
B17: 45330 | C17: Emergency fund SIP | D17: Savings and Investments | E17: 3000 | F17: Auto-Debit
B18: 45337 | C18: T-shirts x3 | D18: Shopping | E18: 1200 | F18: Credit Card
B19: 45352 | C19: Monthly rent | D19: Housing | E19: 18000 | F19: Net Banking | G19: March

Sheet Income Log
B1: INCOME LOG - Enter every payment received here
B2: Total Income Logged: | E2: =SUM(E5:E9999) -> 281920
B3: Date format: 2024-MM-DD | Use dropdown for Source | Amount in numbers only
B4: Date | C4: Description | D4: Source | E4: Amount | F4: Account | G4: Notes
B5: 45292 | C5: January salary | D5: Salary | E5: 85000 | F5: HDFC Bank | G5: Monthly salary
B6: 45306 | C6: Fiverr logo design | D6: Freelance | E6: 3500 | F6: Wallet
B7: 45311 | C7: HDFC dividend | D7: Dividends | E7: 420 | F7: HDFC Bank | G7: Q3 payout
B8: 45323 | C8: February salary | D8: Salary | E8: 85000 | F8: HDFC Bank
B9: 45334 | C9: Website project | D9: Freelance | E9: 8000 | F9: HDFC Bank | G9: Client ABC
B10: 45352 | C10: March salary | D10: Salary | E10: 85000 | F10: HDFC Bank
B11: 45366 | C11: Q1 performance bonus | D11: Bonus | E11: 15000 | F11: HDFC Bank

Sheet Category Analysis
B1: CATEGORY ANALYSIS | 2024 - Auto-calculated from Expense Log
B2: All values pull automatically from Expense Log. Do not edit this sheet.
B4: Category | C4: Annual Total | D4: % of Expenses | E4: Monthly Average
B5: Housing | C5: =SUMIFS('Expense Log'!$E:$E,'Expense Log'!$D:$D,"Housing",'Expense Log'!$B:$B,">="&DATE(2024,1,1),'Expense Log'!$B:$B,"<"&DATE(2025,1,1)) -> 54000 | D5: =IF(SUMIFS('Expense Log'!$E:$E,'Expense Log'!$B:$B,">="&DATE(2024,1,1),'Expense Log'!$B:$B,"<"&DATE(2025,1,1))=0,0,C5/SUMIFS('Expense Log'!$E:$E,'Expense Log'!$B:$B,">="&DATE(2024,1,1),'Expense Log'!$B:$B,"<"&DATE(2025,1,1))) -> 0.73421439 | E5: =C5/12 -> 4500
B6: Food and Groceries | C6: =SUMIFS('Expense Log'!$E:$E,'Expense Log'!$D:$D,"Food and Groceries",'Expense Log'!$B:$B,">="&DATE(2024,1,1),'Expense Log'!$B:$B,"<"&DATE(2025,1,1)) -> 6450 | D6: =IF(SUMIFS('Expense Log'!$E:$E,'Expense Log'!$B:$B,">="&DATE(2024,1,1),'Expense Log'!$B:$B,"<"&DATE(2025,1,1))=0,0,C6/SUMIFS('Expense Log'!$E:$E,'Expense Log'!$B:$B,">="&DATE(2024,1,1),'Expense Log'!$B:$B,"<"&DATE(2025,1,1))) -> 0.08769783 | E6: =C6/12 -> 537.5
B7: Transport | C7: =SUMIFS('Expense Log'!$E:$E,'Expense Log'!$D:$D,"Transport",'Expense Log'!$B:$B,">="&DATE(2024,1,1),'Expense Log'!$B:$B,"<"&DATE(2025,1,1)) -> 1600 | D7: =IF(SUMIFS('Expense Log'!$E:$E,'Expense Log'!$B:$B,">="&DATE(2024,1,1),'Expense Log'!$B:$B,"<"&DATE(2025,1,1))=0,0,C7/SUMIFS('Expense Log'!$E:$E,'Expense Log'!$B:$B,">="&DATE(2024,1,1),'Expense Log'!$B:$B,"<"&DATE(2025,1,1))) -> 0.0217545 | E7: =C7/12 -> 133.33333
B8: Health and Medical | C8: =SUMIFS('Expense Log'!$E:$E,'Expense Log'!$D:$D,"Health and Medical",'Expense Log'!$B:$B,">="&DATE(2024,1,1),'Expense Log'!$B:$B,"<"&DATE(2025,1,1)) -> 700 | D8: =IF(SUMIFS('Expense Log'!$E:$E,'Expense Log'!$B:$B,">="&DATE(2024,1,1),'Expense Log'!$B:$B,"<"&DATE(2025,1,1))=0,0,C8/SUMIFS('Expense Log'!$E:$E,'Expense Log'!$B:$B,">="&DATE(2024,1,1),'Expense Log'!$B:$B,"<"&DATE(2025,1,1))) -> 0.009517594 | E8: =C8/12 -> 58.333333
B9: Education | C9: =SUMIFS('Expense Log'!$E:$E,'Expense Log'!$D:$D,"Education",'Expense Log'!$B:$B,">="&DATE(2024,1,1),'Expense Log'!$B:$B,"<"&DATE(2025,1,1)) -> 499 | D9: =IF(SUMIFS('Expense Log'!$E:$E,'Expense Log'!$B:$B,">="&DATE(2024,1,1),'Expense Log'!$B:$B,"<"&DATE(2025,1,1))=0,0,C9/SUMIFS('Expense Log'!$E:$E,'Expense Log'!$B:$B,">="&DATE(2024,1,1),'Expense Log'!$B:$B,"<"&DATE(2025,1,1))) -> 0.0067846848 | E9: =C9/12 -> 41.583333
B10: Shopping | C10: =SUMIFS('Expense Log'!$E:$E,'Expense Log'!$D:$D,"Shopping",'Expense Log'!$B:$B,">="&DATE(2024,1,1),'Expense Log'!$B:$B,"<"&DATE(2025,1,1)) -> 1200 | D10: =IF(SUMIFS('Expense Log'!$E:$E,'Expense Log'!$B:$B,">="&DATE(2024,1,1),'Expense Log'!$B:$B,"<"&DATE(2025,1,1))=0,0,C10/SUMIFS('Expense Log'!$E:$E,'Expense Log'!$B:$B,">="&DATE(2024,1,1),'Expense Log'!$B:$B,"<"&DATE(2025,1,1))) -> 0.016315875 | E10: =C10/12 -> 100
B11: Subscriptions | C11: =SUMIFS('Expense Log'!$E:$E,'Expense Log'!$D:$D,"Subscriptions",'Expense Log'!$B:$B,">="&DATE(2024,1,1),'Expense Log'!$B:$B,"<"&DATE(2025,1,1)) -> 499 | D11: =IF(SUMIFS('Expense Log'!$E:$E,'Expense Log'!$B:$B,">="&DATE(2024,1,1),'Expense Log'!$B:$B,"<"&DATE(2025,1,1))=0,0,C11/SUMIFS('Expense Log'!$E:$E,'Expense Log'!$B:$B,">="&DATE(2024,1,1),'Expense Log'!$B:$B,"<"&DATE(2025,1,1))) -> 0.0067846848 | E11: =C11/12 -> 41.583333
B12: Entertainment | C12: =SUMIFS('Expense Log'!$E:$E,'Expense Log'!$D:$D,"Entertainment",'Expense Log'!$B:$B,">="&DATE(2024,1,1),'Expense Log'!$B:$B,"<"&DATE(2025,1,1)) -> 600 | D12: =IF(SUMIFS('Expense Log'!$E:$E,'Expense Log'!$B:$B,">="&DATE(2024,1,1),'Expense Log'!$B:$B,"<"&DATE(2025,1,1))=0,0,C12/SUMIFS('Expense Log'!$E:$E,'Expense Log'!$B:$B,">="&DATE(2024,1,1),'Expense Log'!$B:$B,"<"&DATE(2025,1,1))) -> 0.0081579377 | E12: =C12/12 -> 50
B13: Travel | C13: =SUMIFS('Expense Log'!$E:$E,'Expense Log'!$D:$D,"Travel",'Expense Log'!$B:$B,">="&DATE(2024,1,1),'Expense Log'!$B:$B,"<"&DATE(2025,1,1)) -> 0 | D13: =IF(SUMIFS('Expense Log'!$E:$E,'Expense Log'!$B:$B,">="&DATE(2024,1,1),'Expense Log'!$B:$B,"<"&DATE(2025,1,1))=0,0,C13/SUMIFS('Expense Log'!$E:$E,'Expense Log'!$B:$B,">="&DATE(2024,1,1),'Expense Log'!$B:$B,"<"&DATE(2025,1,1))) -> 0 | E13: =C13/12 -> 0
B14: Savings and Investments | C14: =SUMIFS('Expense Log'!$E:$E,'Expense Log'!$D:$D,"Savings and Investments",'Expense Log'!$B:$B,">="&DATE(2024,1,1),'Expense Log'!$B:$B,"<"&DATE(2025,1,1)) -> 8000 | D14: =IF(SUMIFS('Expense Log'!$E:$E,'Expense Log'!$B:$B,">="&DATE(2024,1,1),'Expense Log'!$B:$B,"<"&DATE(2025,1,1))=0,0,C14/SUMIFS('Expense Log'!$E:$E,'Expense Log'!$B:$B,">="&DATE(2024,1,1),'Expense Log'!$B:$B,"<"&DATE(2025,1,1))) -> 0.1087725 | E14: =C14/12 -> 666.66667
B15: Miscellaneous | C15: =SUMIFS('Expense Log'!$E:$E,'Expense Log'!$D:$D,"Miscellaneous",'Expense Log'!$B:$B,">="&DATE(2024,1,1),'Expense Log'!$B:$B,"<"&DATE(2025,1,1)) -> 0 | D15: =IF(SUMIFS('Expense Log'!$E:$E,'Expense Log'!$B:$B,">="&DATE(2024,1,1),'Expense Log'!$B:$B,"<"&DATE(2025,1,1))=0,0,C15/SUMIFS('Expense Log'!$E:$E,'Expense Log'!$B:$B,">="&DATE(2024,1,1),'Expense Log'!$B:$B,"<"&DATE(2025,1,1))) -> 0 | E15: =C15/12 -> 0
B16: TOTAL | C16: =SUMIFS('Expense Log'!$E:$E,'Expense Log'!$B:$B,">="&DATE(2024,1,1),'Expense Log'!$B:$B,"<"&DATE(2025,1,1)) -> 73548 | D16: =1 -> 1 | E16: =C16/12 -> 6129

Sheet Savings Goals
B1: SAVINGS GOALS TRACKER
B2: Enter goal details in white cells. Update the Saved So Far column regularly. Remaining and % Complete auto-calculate.
B4: Goal Name | C4: Target Amount | D4: Saved So Far | E4: Remaining | F4: % Complete | G4: Deadline | H4: Status | I4: Priority
B5: Emergency Fund (6 months expenses) | C5: 300000 | D5: 85000 | E5: =C5-D5 -> 215000 | F5: =IF(C5=0,0,D5/C5) -> 0.28333333 | G5: 2024-06-30 | H5: =IF(D5>=C5,"Complete",IF(D5/C5>=0.8,"Almost there",IF(D5/C5>=0.5,"On track","Started"))) -> Started | I5: High
B6: House Down Payment | C6: 1500000 | D6: 250000 | E6: =C6-D6 -> 1250000 | F6: =IF(C6=0,0,D6/C6) -> 0.16666667 | G6: 2026-12-31 | H6: =IF(D6>=C6,"Complete",IF(D6/C6>=0.8,"Almost there",IF(D6/C6>=0.5,"On track","Started"))) -> Started | I6: High
B7: New Car Fund | C7: 600000 | D7: 120000 | E7: =C7-D7 -> 480000 | F7: =IF(C7=0,0,D7/C7) -> 0.2 | G7: 2025-06-30 | H7: =IF(D7>=C7,"Complete",IF(D7/C7>=0.8,"Almost there",IF(D7/C7>=0.5,"On track","Started"))) -> Started | I7: Medium
B8: Europe Trip | C8: 150000 | D8: 45000 | E8: =C8-D8 -> 105000 | F8: =IF(C8=0,0,D8/C8) -> 0.3 | G8: 2024-12-31 | H8: =IF(D8>=C8,"Complete",IF(D8/C8>=0.8,"Almost there",IF(D8/C8>=0.5,"On track","Started"))) -> Started | I8: Medium
B9: Higher Education | C9: 500000 | D9: 80000 | E9: =C9-D9 -> 420000 | F9: =IF(C9=0,0,D9/C9) -> 0.16 | G9: 2026-06-30 | H9: =IF(D9>=C9,"Complete",IF(D9/C9>=0.8,"Almost there",IF(D9/C9>=0.5,"On track","Started"))) -> Started | I9: High
B10: New Laptop | C10: 80000 | D10: 30000 | E10: =C10-D10 -> 50000 | F10: =IF(C10=0,0,D10/C10) -> 0.375 | G10: 2024-03-31 | H10: =IF(D10>=C10,"Complete",IF(D10/C10>=0.8,"Almost there",IF(D10/C10>=0.5,"On track","Started"))) -> Started | I10: Low
B11: Investment Portfolio | C11: 1000000 | D11: 180000 | E11: =C11-D11 -> 820000 | F11: =IF(C11=0,0,D11/C11) -> 0.18 | G11: 2027-12-31 | H11: =IF(D11>=C11,"Complete",IF(D11/C11>=0.8,"Almost there",IF(D11/C11>=0.5,"On track","Started"))) -> Started | I11: Medium
B12: Wedding Fund | C12: 400000 | D12: 60000 | E12: =C12-D12 -> 340000 | F12: =IF(C12=0,0,D12/C12) -> 0.15 | G12: 2025-12-31 | H12: =IF(D12>=C12,"Complete",IF(D12/C12>=0.8,"Almost there",IF(D12/C12>=0.5,"On track","Started"))) -> Started | I12: Medium
B13: New Phone | C13: 50000 | D13: 50000 | E13: =C13-D13 -> 0 | F13: =IF(C13=0,0,D13/C13) -> 1 | G13: 2024-01-31 | H13: =IF(D13>=C13,"Complete",IF(D13/C13>=0.8,"Almost there",IF(D13/C13>=0.5,"On track","Started"))) -> Complete | I13: Low
B14: Retirement Corpus | C14: 10000000 | D14: 500000 | E14: =C14-D14 -> 9500000 | F14: =IF(C14=0,0,D14/C14) -> 0.05 | G14: 2045-12-31 | H14: =IF(D14>=C14,"Complete",IF(D14/C14>=0.8,"Almost there",IF(D14/C14>=0.5,"On track","Started"))) -> Started | I14: High
B15: TOTAL | C15: =SUM(C5:C14) -> 14580000 | D15: =SUM(D5:D14) -> 1400000 | E15: =SUM(E5:E14) -> 13180000 | F15: =IF(C15=0,0,D15/C15) -> 0.096021948

Sheet Annual Overview
B1: ANNUAL OVERVIEW | 2024 - Auto-calculated from logs
B2: All values come from Expense Log and Income Log via SUMIFS. No manual entry needed.
B4: Month | C4: Income | D4: Expenses | E4: Net Savings | F4: Savings Rate | G4: Running Balance
B5: January | C5: =SUMIFS('Income Log'!$E:$E,'Income Log'!$B:$B,">="&DATE(2024,1,1),'Income Log'!$B:$B,"<"&DATE(2024,2,1)) -> 88920 | D5: =SUMIFS('Expense Log'!$E:$E,'Expense Log'!$B:$B,">="&DATE(2024,1,1),'Expense Log'!$B:$B,"<"&DATE(2024,2,1)) -> 30548 | E5: =C5-D5 -> 58372 | F5: =IF(C5=0,0,E5/C5) -> 0.65645524 | G5: =E5 -> 58372
B6: February | C6: =SUMIFS('Income Log'!$E:$E,'Income Log'!$B:$B,">="&DATE(2024,2,1),'Income Log'!$B:$B,"<"&DATE(2024,3,1)) -> 93000 | D6: =SUMIFS('Expense Log'!$E:$E,'Expense Log'!$B:$B,">="&DATE(2024,2,1),'Expense Log'!$B:$B,"<"&DATE(2024,3,1)) -> 25000 | E6: =C6-D6 -> 68000 | F6: =IF(C6=0,0,E6/C6) -> 0.7311828 | G6: =G5+E6 -> 126372
B7: March | C7: =SUMIFS('Income Log'!$E:$E,'Income Log'!$B:$B,">="&DATE(2024,3,1),'Income Log'!$B:$B,"<"&DATE(2024,4,1)) -> 100000 | D7: =SUMIFS('Expense Log'!$E:$E,'Expense Log'!$B:$B,">="&DATE(2024,3,1),'Expense Log'!$B:$B,"<"&DATE(2024,4,1)) -> 18000 | E7: =C7-D7 -> 82000 | F7: =IF(C7=0,0,E7/C7) -> 0.82 | G7: =G6+E7 -> 208372
B8: April | C8: =SUMIFS('Income Log'!$E:$E,'Income Log'!$B:$B,">="&DATE(2024,4,1),'Income Log'!$B:$B,"<"&DATE(2024,5,1)) -> 0 | D8: =SUMIFS('Expense Log'!$E:$E,'Expense Log'!$B:$B,">="&DATE(2024,4,1),'Expense Log'!$B:$B,"<"&DATE(2024,5,1)) -> 0 | E8: =C8-D8 -> 0 | F8: =IF(C8=0,0,E8/C8) -> 0 | G8: =G7+E8 -> 208372
B9: May | C9: =SUMIFS('Income Log'!$E:$E,'Income Log'!$B:$B,">="&DATE(2024,5,1),'Income Log'!$B:$B,"<"&DATE(2024,6,1)) -> 0 | D9: =SUMIFS('Expense Log'!$E:$E,'Expense Log'!$B:$B,">="&DATE(2024,5,1),'Expense Log'!$B:$B,"<"&DATE(2024,6,1)) -> 0 | E9: =C9-D9 -> 0 | F9: =IF(C9=0,0,E9/C9) -> 0 | G9: =G8+E9 -> 208372
B10: June | C10: =SUMIFS('Income Log'!$E:$E,'Income Log'!$B:$B,">="&DATE(2024,6,1),'Income Log'!$B:$B,"<"&DATE(2024,7,1)) -> 0 | D10: =SUMIFS('Expense Log'!$E:$E,'Expense Log'!$B:$B,">="&DATE(2024,6,1),'Expense Log'!$B:$B,"<"&DATE(2024,7,1)) -> 0 | E10: =C10-D10 -> 0 | F10: =IF(C10=0,0,E10/C10) -> 0 | G10: =G9+E10 -> 208372
B11: July | C11: =SUMIFS('Income Log'!$E:$E,'Income Log'!$B:$B,">="&DATE(2024,7,1),'Income Log'!$B:$B,"<"&DATE(2024,8,1)) -> 0 | D11: =SUMIFS('Expense Log'!$E:$E,'Expense Log'!$B:$B,">="&DATE(2024,7,1),'Expense Log'!$B:$B,"<"&DATE(2024,8,1)) -> 0 | E11: =C11-D11 -> 0 | F11: =IF(C11=0,0,E11/C11) -> 0 | G11: =G10+E11 -> 208372
B12: August | C12: =SUMIFS('Income Log'!$E:$E,'Income Log'!$B:$B,">="&DATE(2024,8,1),'Income Log'!$B:$B,"<"&DATE(2024,9,1)) -> 0 | D12: =SUMIFS('Expense Log'!$E:$E,'Expense Log'!$B:$B,">="&DATE(2024,8,1),'Expense Log'!$B:$B,"<"&DATE(2024,9,1)) -> 0 | E12: =C12-D12 -> 0 | F12: =IF(C12=0,0,E12/C12) -> 0 | G12: =G11+E12 -> 208372
B13: September | C13: =SUMIFS('Income Log'!$E:$E,'Income Log'!$B:$B,">="&DATE(2024,9,1),'Income Log'!$B:$B,"<"&DATE(2024,10,1)) -> 0 | D13: =SUMIFS('Expense Log'!$E:$E,'Expense Log'!$B:$B,">="&DATE(2024,9,1),'Expense Log'!$B:$B,"<"&DATE(2024,10,1)) -> 0 | E13: =C13-D13 -> 0 | F13: =IF(C13=0,0,E13/C13) -> 0 | G13: =G12+E13 -> 208372
B14: October | C14: =SUMIFS('Income Log'!$E:$E,'Income Log'!$B:$B,">="&DATE(2024,10,1),'Income Log'!$B:$B,"<"&DATE(2024,11,1)) -> 0 | D14: =SUMIFS('Expense Log'!$E:$E,'Expense Log'!$B:$B,">="&DATE(2024,10,1),'Expense Log'!$B:$B,"<"&DATE(2024,11,1)) -> 0 | E14: =C14-D14 -> 0 | F14: =IF(C14=0,0,E14/C14) -> 0 | G14: =G13+E14 -> 208372
B15: November | C15: =SUMIFS('Income Log'!$E:$E,'Income Log'!$B:$B,">="&DATE(2024,11,1),'Income Log'!$B:$B,"<"&DATE(2024,12,1)) -> 0 | D15: =SUMIFS('Expense Log'!$E:$E,'Expense Log'!$B:$B,">="&DATE(2024,11,1),'Expense Log'!$B:$B,"<"&DATE(2024,12,1)) -> 0 | E15: =C15-D15 -> 0 | F15: =IF(C15=0,0,E15/C15) -> 0 | G15: =G14+E15 -> 208372
B16: December | C16: =SUMIFS('Income Log'!$E:$E,'Income Log'!$B:$B,">="&DATE(2024,12,1),'Income Log'!$B:$B,"<"&DATE(2025,1,1)) -> 0 | D16: =SUMIFS('Expense Log'!$E:$E,'Expense Log'!$B:$B,">="&DATE(2024,12,1),'Expense Log'!$B:$B,"<"&DATE(2025,1,1)) -> 0 | E16: =C16-D16 -> 0 | F16: =IF(C16=0,0,E16/C16) -> 0 | G16: =G15+E16 -> 208372
B17: ANNUAL TOTAL | C17: =SUM(C5:C16) -> 281920 | D17: =SUM(D5:D16) -> 73548 | E17: =SUM(E5:E16) -> 208372 | F17: =IF(C17=0,0,E17/C17) -> 0.73911748 | G17: =G16 -> 208372
B19: KEY STATISTICS
B20: Metric | C20: Value
B21: Best month (highest savings) | C21: =INDEX(B5:B16,MATCH(MAX(E5:E16),E5:E16,0)) -> March
B22: Worst month (lowest savings) | C22: =INDEX(B5:B16,MATCH(MIN(E5:E16),E5:E16,0)) -> April
B23: Average monthly income | C23: =AVERAGE(C5:C16) -> 23493.333
B24: Average monthly expenses | C24: =AVERAGE(D5:D16) -> 6129
B25: Average monthly savings | C25: =AVERAGE(E5:E16) -> 17364.333
B26: Overall savings rate | C26: =IF(C17=0,0,E17/C17) -> 0.73911748
